23:40:48,614 root INFO Running Urban Planning
23:40:48,627 urllib3.connectionpool DEBUG Starting new HTTPS connection (1): api.telegram.org:443
23:40:49,4 urllib3.connectionpool DEBUG https://api.telegram.org:443 "GET /bot5817634117:AAHFVRVHdtNo34mEsrAIlQzPFxZphT20aqE/getMe HTTP/1.1" 200 204
23:40:49,12 urllib3.connectionpool DEBUG Starting new HTTPS connection (1): api.telegram.org:443
23:40:52,805 urllib3.connectionpool DEBUG https://api.telegram.org:443 "GET /bot5817634117:AAHFVRVHdtNo34mEsrAIlQzPFxZphT20aqE/getUpdates?offset=1&timeout=20 HTTP/1.1" 409 143
23:40:52,814 TeleBot ERROR Threaded polling exception: A request to the Telegram API was unsuccessful. Error code: 409. Description: Conflict: terminated by other getUpdates request; make sure that only one bot instance is running
23:40:52,816 TeleBot ERROR Exception traceback:
Traceback (most recent call last):
  File "C:\Users\MuradZM\.virtualenvs\bot_v7-TZeifAca\Lib\site-packages\telebot\__init__.py", line 1073, in __threaded_polling
    polling_thread.raise_exceptions()
  File "C:\Users\MuradZM\.virtualenvs\bot_v7-TZeifAca\Lib\site-packages\telebot\util.py", line 118, in raise_exceptions
    raise self.exception_info
  File "C:\Users\MuradZM\.virtualenvs\bot_v7-TZeifAca\Lib\site-packages\telebot\util.py", line 100, in run
    task(*args, **kwargs)
  File "C:\Users\MuradZM\.virtualenvs\bot_v7-TZeifAca\Lib\site-packages\telebot\__init__.py", line 649, in __retrieve_updates
    updates = self.get_updates(offset=(self.last_update_id + 1),
             ^^^^^^^^^^^^^^^^^^^^^^^^^^^^^^^^^^^^^^^^^^^^^^^^^^^
  File "C:\Users\MuradZM\.virtualenvs\bot_v7-TZeifAca\Lib\site-packages\telebot\__init__.py", line 623, in get_updates
    json_updates = apihelper.get_updates(self.token, offset, limit, timeout, allowed_updates, long_polling_timeout)
                   ^^^^^^^^^^^^^^^^^^^^^^^^^^^^^^^^^^^^^^^^^^^^^^^^^^^^^^^^^^^^^^^^^^^^^^^^^^^^^^^^^^^^^^^^^^^^^^^^
  File "C:\Users\MuradZM\.virtualenvs\bot_v7-TZeifAca\Lib\site-packages\telebot\apihelper.py", line 321, in get_updates
    return _make_request(token, method_url, params=payload)
           ^^^^^^^^^^^^^^^^^^^^^^^^^^^^^^^^^^^^^^^^^^^^^^^^
  File "C:\Users\MuradZM\.virtualenvs\bot_v7-TZeifAca\Lib\site-packages\telebot\apihelper.py", line 162, in _make_request
    json_result = _check_result(method_name, result)
                  ^^^^^^^^^^^^^^^^^^^^^^^^^^^^^^^^^^
  File "C:\Users\MuradZM\.virtualenvs\bot_v7-TZeifAca\Lib\site-packages\telebot\apihelper.py", line 189, in _check_result
    raise ApiTelegramException(method_name, result, result_json)
telebot.apihelper.ApiTelegramException: A request to the Telegram API was unsuccessful. Error code: 409. Description: Conflict: terminated by other getUpdates request; make sure that only one bot instance is running

23:40:56,810 urllib3.connectionpool DEBUG https://api.telegram.org:443 "GET /bot5817634117:AAHFVRVHdtNo34mEsrAIlQzPFxZphT20aqE/getUpdates?offset=1&timeout=20 HTTP/1.1" 409 143
23:40:56,815 TeleBot ERROR Threaded polling exception: A request to the Telegram API was unsuccessful. Error code: 409. Description: Conflict: terminated by other getUpdates request; make sure that only one bot instance is running
23:40:56,822 TeleBot ERROR Exception traceback:
Traceback (most recent call last):
  File "C:\Users\MuradZM\.virtualenvs\bot_v7-TZeifAca\Lib\site-packages\telebot\__init__.py", line 1073, in __threaded_polling
    polling_thread.raise_exceptions()
  File "C:\Users\MuradZM\.virtualenvs\bot_v7-TZeifAca\Lib\site-packages\telebot\util.py", line 118, in raise_exceptions
    raise self.exception_info
  File "C:\Users\MuradZM\.virtualenvs\bot_v7-TZeifAca\Lib\site-packages\telebot\util.py", line 100, in run
    task(*args, **kwargs)
  File "C:\Users\MuradZM\.virtualenvs\bot_v7-TZeifAca\Lib\site-packages\telebot\__init__.py", line 649, in __retrieve_updates
    updates = self.get_updates(offset=(self.last_update_id + 1),
             ^^^^^^^^^^^^^^^^^^^^^^^^^^^^^^^^^^^^^^^^^^^^^^^^^^^
  File "C:\Users\MuradZM\.virtualenvs\bot_v7-TZeifAca\Lib\site-packages\telebot\__init__.py", line 623, in get_updates
    json_updates = apihelper.get_updates(self.token, offset, limit, timeout, allowed_updates, long_polling_timeout)
                   ^^^^^^^^^^^^^^^^^^^^^^^^^^^^^^^^^^^^^^^^^^^^^^^^^^^^^^^^^^^^^^^^^^^^^^^^^^^^^^^^^^^^^^^^^^^^^^^^
  File "C:\Users\MuradZM\.virtualenvs\bot_v7-TZeifAca\Lib\site-packages\telebot\apihelper.py", line 321, in get_updates
    return _make_request(token, method_url, params=payload)
           ^^^^^^^^^^^^^^^^^^^^^^^^^^^^^^^^^^^^^^^^^^^^^^^^
  File "C:\Users\MuradZM\.virtualenvs\bot_v7-TZeifAca\Lib\site-packages\telebot\apihelper.py", line 162, in _make_request
    json_result = _check_result(method_name, result)
                  ^^^^^^^^^^^^^^^^^^^^^^^^^^^^^^^^^^
  File "C:\Users\MuradZM\.virtualenvs\bot_v7-TZeifAca\Lib\site-packages\telebot\apihelper.py", line 189, in _check_result
    raise ApiTelegramException(method_name, result, result_json)
telebot.apihelper.ApiTelegramException: A request to the Telegram API was unsuccessful. Error code: 409. Description: Conflict: terminated by other getUpdates request; make sure that only one bot instance is running

